<?xml version="1.0" encoding="utf-8"?>
<!-- This URDF was automatically created by SolidWorks to URDF Exporter! Originally created by Stephen Brawner (brawner@gmail.com) 
     Commit Version: 1.6.0-4-g7f85cfe  Build Version: 1.6.7995.38578
     For more information, please see http://wiki.ros.org/sw_urdf_exporter -->
<robot
  name="tn5">
  <link
    name="base_link">
    <inertial>
      <origin
        xyz="0.0184615630654843 0.000708732696882722 0.0213471859477455"
        rpy="0 0 0" />
      <mass
        value="0.196920604974914" />
      <inertia
        ixx="0.000120591624612605"
        ixy="-1.79744474162922E-08"
        ixz="4.22690883448594E-08"
        iyy="0.000460661351785231"
        iyz="-1.80762204519505E-08"
        izz="0.000572821161554506" />
    </inertial>
    <visual>
      <origin
        xyz="0 0 0"
        rpy="0 0 0" />
      <geometry>
        <mesh
          filename="package://tn5/meshes/base_link.STL" />
      </geometry>
      <material
        name="">
        <color
          rgba="0.792156862745098 0.819607843137255 0.933333333333333 1" />
      </material>
    </visual>
    <collision>
      <origin
        xyz="0 0 0"
        rpy="0 0 0" />
      <geometry>
        <mesh
          filename="package://tn5/meshes/base_link.STL" />
      </geometry>
      <surface>
        <friction>
          <ode>
            <mu>0.1</mu>  <!-- Giảm ma sát ngang -->
            <mu2>0.1</mu2> <!-- Giảm ma sát dọc -->
          </ode>
        </friction>
      </surface>
    </collision>
  </link>

  
  
<link name="wheel_left_link">
    <inertial>
        <origin xyz="-5.29067580209985E-06 0.000207292329300446 0.0094632476681986" rpy="0 0 0" />
        <mass value="0.0184660869771916" />
        <inertia
            ixx="4.8E-06"
            ixy="0.0"
            ixz="0.0"
            iyy="4.8E-06"
            iyz="0.0"
            izz="7.5E-06" />
    </inertial>
    <visual>
        <origin xyz="0 0 0" rpy="0 0 0" />
        <geometry>
            <mesh filename="package://tn5/meshes/wheel_left_link.STL" />
        </geometry>
        <material name="">
            <color rgba="0.792 0.819 0.933 1" />
        </material>
    </visual>
    <collision>
        <origin xyz="0 0 0" rpy="0 0 0" />
        <geometry>
            <mesh filename="package://tn5/meshes/wheel_left_link.STL" />
        </geometry>
        <surface>
            <friction>
                <ode>
                    <mu>0.11</mu>  <!-- Điều chỉnh ma sát giống bánh phải -->
                    <mu2>0.11</mu2>
                </ode>
            </friction>
            <contact>
                <ode>
                    <kp>50</kp>
                    <kd>1.0</kd>
                </ode>
            </contact>
        </surface>
    </collision>
</link>

<joint name="wheel_left_link_joint" type="continuous">
    <origin xyz="-0.04058 0.065333 0.01093" rpy="1.5708 0 0" />
    <parent link="base_link" />
    <child link="wheel_left_link" />
    <axis xyz="0.0038265 0 0.99999" />
    <dynamics damping="0.005" friction="0.005" />  <!-- Đồng bộ với bánh phải -->
    <gazebo>
        <joint name="wheel_left_link_joint">
            <pid p="2.5" i="0.3" d="0.01" />  <!-- Cùng thông số PID với bánh phải để xe chạy cân bằng -->
        </joint>
    </gazebo>
</joint>






  <link name="wheel_right_link">
    <inertial>
        <origin xyz="2.67592658947935E-07 5.91954136998363E-06 -0.00972425576539476" rpy="0 0 0" />
        <mass value="0.0188356493917418" />
        <inertia
            ixx="4.5E-06"
            ixy="0.0"
            ixz="0.0"
            iyy="4.5E-06"
            iyz="0.0"
            izz="7.0E-06" />
    </inertial>
    <visual>
        <origin xyz="0 0 0" rpy="0 0 0" />
        <geometry>
            <mesh filename="package://tn5/meshes/wheel_right_link.STL" />
        </geometry>
        <material name="">
            <color rgba="0.792 0.819 0.933 1" />
        </material>
    </visual>
    <collision>
        <origin xyz="0 0 0" rpy="0 0 0" />
        <geometry>
            <mesh filename="package://tn5/meshes/wheel_right_link.STL" />
        </geometry>
        <surface>
            <friction>
                <ode>
                    <mu>0.11</mu>  <!-- Giảm ma sát, giúp bánh không bị bám quá chặt -->
                    <mu2>0.11</mu2>
                </ode>
            </friction>
            <contact>
                <ode>
                    <kp>500</kp>
                    <kd>1.0</kd>
                </ode>
            </contact>
        </surface>
    </collision>
</link>

<joint name="wheel_right_link_joint" type="continuous">
    <origin xyz="-0.04008 -0.065335 0.01093" rpy="1.5708 0 0" />
    <parent link="base_link" />
    <child link="wheel_right_link" />
    <axis xyz="0.0038265 0 0.99999" />
    <dynamics damping="0.005" friction="0.005" />  <!-- Giảm damping & friction để bánh xe quay trơn hơn -->
    <gazebo>
        <joint name="wheel_right_link_joint">
            <pid p="2.5" i="0.3" d="0.01" />  <!-- Giảm P để hạn chế giật -->
        </joint>
    </gazebo>
</joint>

 

  
  
  
  
  
  
  
  
  
  <link
    name="lidar_link">
    <inertial>
      <origin
        xyz="0.00676653011666362 -0.000207827566854599 -0.0224318722671598"
        rpy="0 0 0" />
      <mass
        value="1.33076913637071" />
      <inertia
        ixx="0.000614917940454091"
        ixy="-8.01984318976279E-07"
        ixz="0.00015824302591117"
        iyy="0.000960697335617224"
        iyz="-3.09162986587525E-06"
        izz="0.00109815200027136" />
    </inertial>
    <visual>
      <origin
        xyz="0 0 0"
        rpy="0 0 0" />
      <geometry>
        <mesh
          filename="package://tn5/meshes/lidar_link.STL" />
      </geometry>
      <material
        name="">
        <color
          rgba="0.792156862745098 0.819607843137255 0.933333333333333 1" />
      </material>
    </visual>
    <collision>
      <origin
        xyz="0 0 0"
        rpy="0 0 0" />
      <geometry>
        <mesh
          filename="package://tn5/meshes/lidar_link.STL" />
      </geometry>
    </collision>
  </link>
  <joint
    name="lidar_link_joint"
    type="fixed">
    <origin
      xyz="0.0016672 -0.00028475 0.06363"
      rpy="0 0 0" />
    <parent
      link="base_link" />
    <child
      link="lidar_link" />
    <axis
      xyz="0 0 0" />
  </joint>
  <link
    name="camera_link">
    <inertial>
      <origin
        xyz="-0.0147044597232891 5.41606455101151E-08 -0.005869470677028"
        rpy="0 0 0" />
      <mass
        value="0.054335270667199" />
      <inertia
        ixx="2.2633421635547E-05"
        ixy="-5.40721678471557E-12"
        ixz="1.45380028902577E-07"
        iyy="7.00114916721175E-06"
        iyz="1.02807140333885E-11"
        izz="2.03635502398026E-05" />
    </inertial>
    <visual>
      <origin
        xyz="0 0 0"
        rpy="0 0 0" />
      <geometry>
        <mesh
          filename="package://tn5/meshes/camera_link.STL" />
      </geometry>
      <material
        name="">
        <color
          rgba="0.792156862745098 0.819607843137255 0.933333333333333 1" />
      </material>
    </visual>
    <collision>
      <origin
        xyz="0 0 0"
        rpy="0 0 0" />
      <geometry>
        <mesh
          filename="package://tn5/meshes/camera_link.STL" />
      </geometry>
    </collision>
  </link>
  <joint
    name="camera_link_joint"
    type="fixed">
    <origin
      xyz="0.11508 0.0034935 0.076588"
      rpy="2.2828E-05 0.0041954 -0.00025503" />
    <parent
      link="base_link" />
    <child
      link="camera_link" />
    <axis
      xyz="0 0 0" />
  </joint>
  <link
    name="imu_link">
    <inertial>
      <origin
        xyz="0 6.93889390390723E-18 -0.0015"
        rpy="0 0 0" />
      <mass
        value="0.00552876110196154" />
      <inertia
        ixx="8.01201327713732E-07"
        ixy="-1.29986205481237E-22"
        ixz="-3.50776247675964E-39"
        iyy="1.14517257565508E-06"
        iyz="5.25238777845289E-24"
        izz="1.93808076171587E-06" />
    </inertial>
    <visual>
      <origin
        xyz="0 0 0"
        rpy="0 0 0" />
      <geometry>
        <mesh
          filename="package://tn5/meshes/imu_link.STL" />
      </geometry>
      <material
        name="">
        <color
          rgba="0.792156862745098 0.819607843137255 0.933333333333333 1" />
      </material>
    </visual>
    <collision>
      <origin
        xyz="0 0 0"
        rpy="0 0 0" />
      <geometry>
        <mesh
          filename="package://tn5/meshes/imu_link.STL" />
      </geometry>
    </collision>
  </link>
  <joint
    name="imu_joint"
    type="fixed">
    <origin
      xyz="-0.07353 0.00045071 0.00893"
      rpy="0 0 0" />
    <parent
      link="base_link" />
    <child
      link="imu_link" />
    <axis
      xyz="0 0 0" />
  </joint>
  <link
    name="trutaymay_link">
    <inertial>
      <origin
        xyz="-0.000561626440149815 4.85853147557044E-05 0.0480342292105829"
        rpy="0 0 0" />
      <mass
        value="0.133680310101314" />
      <inertia
        ixx="0.000142407646860895"
        ixy="-2.23893703002711E-08"
        ixz="1.88854868092067E-07"
        iyy="0.00019612798037322"
        iyz="-3.1769375154775E-08"
        izz="6.35632268401285E-05" />
    </inertial>
    <visual>
      <origin
        xyz="0 0 0"
        rpy="0 0 0" />
      <geometry>
        <mesh
          filename="package://tn5/meshes/trutaymay_link.STL" />
      </geometry>
      <material
        name="">
        <color
          rgba="0.792156862745098 0.819607843137255 0.933333333333333 1" />
      </material>
    </visual>
    <collision>
      <origin
        xyz="0 0 0"
        rpy="0 0 0" />
      <geometry>
        <mesh
          filename="package://tn5/meshes/trutaymay_link.STL" />
      </geometry>
    </collision>
  </link>
  <joint
    name="trutaymay_link_joint"
    type="fixed">
    <origin
      xyz="0.0077106770451147 -5.50440355985213E-05 0.09893"
      rpy="0 0 0" />
    <parent
      link="base_link" />
    <child
      link="trutaymay_link" />
    <axis
      xyz="0 0 0" />
  </joint>
  <link
    name="khau1_link">
    <inertial>
      <origin
        xyz="-1.65009625339996E-05 0.0500631015603138 0.00250000000000004"
        rpy="0 0 0" />
      <mass
        value="0.0132171399353069" />
      <inertia
        ixx="1.31950175938831E-05"
        ixy="4.10275718062925E-09"
        ixz="4.01770149829674E-23"
        iyy="7.47457236524674E-07"
        iyz="-1.83493549551987E-22"
        izz="1.38874034140106E-05" />
    </inertial>
    <visual>
      <origin
        xyz="0 0 0"
        rpy="0 0 0" />
      <geometry>
        <mesh
          filename="package://tn5/meshes/khau1_link.STL" />
      </geometry>
      <material
        name="">
        <color
          rgba="0.792156862745098 0.819607843137255 0.933333333333333 1" />
      </material>
    </visual>
    <collision>
      <origin
        xyz="0 0 0"
        rpy="0 0 0" />
      <geometry>
        <mesh
          filename="package://tn5/meshes/khau1_link.STL" />
      </geometry>
    </collision>
  </link>
  <joint
    name="khau1_link_joint"
    type="revolute">
    <origin
      xyz="-0.00059275 0.0025541 0.09"
      rpy="1.5708 0 0" />
    <parent
      link="trutaymay_link" />
    <child
      link="khau1_link" />
    <axis
      xyz="0 0 1" />
    <limit
      lower="-0.5"
      upper="0.5"
      effort="1"
      velocity="1" />
    <dynamics
      damping="0.01"
      friction="0.01" />
  </joint>
  <link
    name="khau2_link">
    <inertial>
      <origin
        xyz="-0.0243789684193669 0.0435816412378846 -0.0025"
        rpy="0 0 0" />
      <mass
        value="0.0132171399353069" />
      <inertia
        ixx="1.02283307610659E-05"
        ixy="5.30347051292619E-06"
        ixz="8.32403066654503E-23"
        iyy="3.71414406934181E-06"
        iyz="-1.32504254393304E-22"
        izz="1.38874034140106E-05" />
    </inertial>
    <visual>
      <origin
        xyz="0 0 0"
        rpy="0 0 0" />
      <geometry>
        <mesh
          filename="package://tn5/meshes/khau2_link.STL" />
      </geometry>
      <material
        name="">
        <color
          rgba="0.792156862745098 0.819607843137255 0.933333333333333 1" />
      </material>
    </visual>
    <collision>
      <origin
        xyz="0 0 0"
        rpy="0 0 0" />
      <geometry>
        <mesh
          filename="package://tn5/meshes/khau2_link.STL" />
      </geometry>
    </collision>
  </link>
  <joint
    name="khau2_link_joint"
    type="revolute">
    <origin
      xyz="-3.296E-05 0.1 0"
      rpy="0 0 0" />
    <parent
      link="khau1_link" />
    <child
      link="khau2_link" />
    <axis
      xyz="0 0 1" />
    <limit
      lower="-0.5"
      upper="0.5"
      effort="1"
      velocity="1" />
    <dynamics
      damping="0.01"
      friction="0.01" />
  </joint>
  
  
  
  
  
  
  
  
  
  
  
  
  
  
  
  
<gazebo reference="imu_link">
  <sensor name="imu_sensor" type="imu">
    <always_on>true</always_on>
    <update_rate>100</update_rate>
    <visualize>true</visualize> 
    <scale>0.1 0.1 0.1</scale>
    <plugin filename="libgazebo_ros_imu_sensor.so" name="imu_plugin">
      <topicName>/imu</topicName>
      <bodyName>imu_link</bodyName>
      <frameName>imu_link</frameName>
      <gaussianNoise>0.01</gaussianNoise>
      <xyzOffset>0 0 0</xyzOffset>
      <rpyOffset>0 0 0</rpyOffset> 
      <initialOrientationAsReference>false</initialOrientationAsReference>
    </plugin>
    <pose>0 0 0 0 1.5708 0</pose> 
  </sensor>
  </gazebo>
  
  
  
  
  
  
  
  
  
  
  
  



 <gazebo>
  <plugin name="differential_drive_controller" filename="libgazebo_ros_diff_drive.so">
    <updateRate>100</updateRate>
    <leftJoint>wheel_left_link_joint</leftJoint>
    <rightJoint>wheel_right_link_joint</rightJoint>
    
    <wheelSeparation>0.5380</wheelSeparation>
    <wheelDiameter>0.2410</wheelDiameter>
    <wheelAcceleration>0.5</wheelAcceleration>
    <wheelTorque>20</wheelTorque>
    <commandTopic>cmd_vel</commandTopic>
    <odometryTopic>odom</odometryTopic>
    <odometryFrame>odom</odometryFrame>
    <robotBaseFrame>base_link</robotBaseFrame>
    <odometrySource>1</odometrySource>
    <publishWheelTF>true</publishWheelTF>
    <publishOdom>true</publishOdom>
        <publishWheelJointState>true</publishWheelJointState>
        

    <legacyMode>false</legacyMode>
  </plugin>
</gazebo>








<gazebo reference="lidar_link">
  <sensor type="ray" name="lidar_sensor">
    <pose>0 0 0 0 0 0</pose>
    <visualize>true</visualize>
    <update_rate>30</update_rate>
    <ray>
      <scan>
        <horizontal>
          <samples>720</samples>
          <resolution>1</resolution>
          <min_angle>-3.1416</min_angle>  <!-- Sửa để quét 360 độ -->
          <max_angle>3.1416</max_angle>   <!-- Sửa để quét 360 độ -->
        </horizontal>
      </scan>
      <range>
        <min>0.1</min>
        <max>30.0</max>
        <resolution>0.01</resolution>
      </range>
      <noise>
        <type>gaussian</type>
        <mean>0.0</mean>
        <stddev>0.01</stddev>
      </noise>
    </ray>
    <plugin name="gazebo_ros_laser" filename="libgazebo_ros_laser.so">
      <topicName>/scan</topicName>
      <frameName>lidar_link</frameName>
    </plugin>
  </sensor>
</gazebo>
<gazebo reference="camera_link">
  <sensor type="camera" name="camera1">
    <update_rate>30.0</update_rate>
    <camera name="head">
      <horizontal_fov>1.3962634</horizontal_fov>
      <image>
        <width>800</width>
        <height>800</height>
        <format>R8G8B8</format>
      </image>
      <clip>
        <near>0.02</near>
        <far>300</far>
      </clip>
      <noise>
        <type>gaussian</type>
        <mean>0.0</mean>
        <stddev>0.007</stddev>
      </noise>
    </camera>
    <plugin name="camera_controller" filename="libgazebo_ros_camera.so">
      <alwaysOn>true</alwaysOn>
      <updateRate>0.0</updateRate>
      <cameraName>rrbot/camera1</cameraName>
      <imageTopicName>image_raw</imageTopicName>
      <cameraInfoTopicName>camera_info</cameraInfoTopicName>
      <frameName>camera_link</frameName>  <!-- Sửa từ camera-link thành camera_link -->
      <hackBaseline>0.07</hackBaseline>
      <distortionK1>0.0</distortionK1>
      <distortionK2>0.0</distortionK2>
      <distortionK3>0.0</distortionK3>
      <distortionT1>0.0</distortionT1>
      <distortionT2>0.0</distortionT2>
    </plugin>
  </sensor>
</gazebo>


	<gazebo>
    <plugin name="gazebo_ros_control" filename="libgazebo_ros_control.so"/>
</gazebo>




<transmission name="khau1_trans">
    <type>transmission_interface/SimpleTransmission</type>
    <joint name="khau1_link_joint">
        <hardwareInterface>hardware_interface/EffortJointInterface</hardwareInterface>
    </joint>
    <actuator name="khau1_actuator">
        <hardwareInterface>hardware_interface/EffortJointInterface</hardwareInterface>
        <mechanicalReduction>1.0</mechanicalReduction>
    </actuator>
</transmission>

<transmission name="khau2_trans">
    <type>transmission_interface/SimpleTransmission</type>
    <joint name="khau2_link_joint">
        <hardwareInterface>hardware_interface/EffortJointInterface</hardwareInterface>
    </joint>
    <actuator name="khau2_actuator">
        <hardwareInterface>hardware_interface/EffortJointInterface</hardwareInterface>
        <mechanicalReduction>1.0</mechanicalReduction>
    </actuator>
</transmission>
  
  
  
  
  
  
  
  
</robot>
